Workbook

Sheet Kilns
A1: Category | B1: Model # | C1: Base Controller | D1: Base Price | E1: Upgrade to KilnStar | F1: Upgrade to Genesis | G1: Base Distributor $ | H1: KilnStar Upgrade D$ | I1: Genesis Upgrade D$
A2: HotBox Kilns (120V) | B2: HB64E | C2: Spark | D2: 1235 | E2: =IF(OR($C2="KilnStar",$D2="",INDEX('Controller Prices'!$D:$D,MATCH($B2,'Controller Prices'!$B:$B,0))=""),"",INDEX('Controller Prices'!$D:$D,MATCH($B2,'Controller Prices'!$B:$B,0))-$D2) | F2: =IF(OR($D2="",INDEX('Controller Prices'!$E:$E,MATCH($B2,'Controller Prices'!$B:$B,0))=""),"",INDEX('Controller Prices'!$E:$E,MATCH($B2,'Controller Prices'!$B:$B,0))-$D2) | G2: 741 | H2: =IF(OR($C2="KilnStar",$G2="",INDEX('Controller Prices'!$H:$H,MATCH($B2,'Controller Prices'!$B:$B,0))=""),"",INDEX('Controller Prices'!$H:$H,MATCH($B2,'Controller Prices'!$B:$B,0))-$G2) | I2: =IF(OR($G2="",INDEX('Controller Prices'!$I:$I,MATCH($B2,'Controller Prices'!$B:$B,0))=""),"",INDEX('Controller Prices'!$I:$I,MATCH($B2,'Controller Prices'!$B:$B,0))-$G2)
A3: HotBox Kilns (120V) | B3: HotboxE | C3: Spark | D3: 1365 | E3: =IF(OR($C3="KilnStar",$D3="",INDEX('Controller Prices'!$D:$D,MATCH($B3,'Controller Prices'!$B:$B,0))=""),"",INDEX('Controller Prices'!$D:$D,MATCH($B3,'Controller Prices'!$B:$B,0))-$D3) | F3: =IF(OR($D3="",INDEX('Controller Prices'!$E:$E,MATCH($B3,'Controller Prices'!$B:$B,0))=""),"",INDEX('Controller Prices'!$E:$E,MATCH($B3,'Controller Prices'!$B:$B,0))-$D3) | G3: 819 | H3: =IF(OR($C3="KilnStar",$G3="",INDEX('Controller Prices'!$H:$H,MATCH($B3,'Controller Prices'!$B:$B,0))=""),"",INDEX('Controller Prices'!$H:$H,MATCH($B3,'Controller Prices'!$B:$B,0))-$G3) | I3: =IF(OR($G3="",INDEX('Controller Prices'!$I:$I,MATCH($B3,'Controller Prices'!$B:$B,0))=""),"",INDEX('Controller Prices'!$I:$I,MATCH($B3,'Controller Prices'!$B:$B,0))-$G3)
A4: HotBox Kilns (120V) | B4: HB84E | C4: Spark | D4: 1525 | E4: =IF(OR($C4="KilnStar",$D4="",INDEX('Controller Prices'!$D:$D,MATCH($B4,'Controller Prices'!$B:$B,0))=""),"",INDEX('Controller Prices'!$D:$D,MATCH($B4,'Controller Prices'!$B:$B,0))-$D4) | F4: =IF(OR($D4="",INDEX('Controller Prices'!$E:$E,MATCH($B4,'Controller Prices'!$B:$B,0))=""),"",INDEX('Controller Prices'!$E:$E,MATCH($B4,'Controller Prices'!$B:$B,0))-$D4) | G4: 915 | H4: =IF(OR($C4="KilnStar",$G4="",INDEX('Controller Prices'!$H:$H,MATCH($B4,'Controller Prices'!$B:$B,0))=""),"",INDEX('Controller Prices'!$H:$H,MATCH($B4,'Controller Prices'!$B:$B,0))-$G4) | I4: =IF(OR($G4="",INDEX('Controller Prices'!$I:$I,MATCH($B4,'Controller Prices'!$B:$B,0))=""),"",INDEX('Controller Prices'!$I:$I,MATCH($B4,'Controller Prices'!$B:$B,0))-$G4)
A5: HotBox Kilns (120V) | B5: HB86E | C5: KilnStar | D5: 1450 | E5: =IF(OR($C5="KilnStar",$D5="",INDEX('Controller Prices'!$D:$D,MATCH($B5,'Controller Prices'!$B:$B,0))=""),"",INDEX('Controller Prices'!$D:$D,MATCH($B5,'Controller Prices'!$B:$B,0))-$D5) | F5: =IF(OR($D5="",INDEX('Controller Prices'!$E:$E,MATCH($B5,'Controller Prices'!$B:$B,0))=""),"",INDEX('Controller Prices'!$E:$E,MATCH($B5,'Controller Prices'!$B:$B,0))-$D5) -> 150 | G5: 870 | H5: =IF(OR($C5="KilnStar",$G5="",INDEX('Controller Prices'!$H:$H,MATCH($B5,'Controller Prices'!$B:$B,0))=""),"",INDEX('Controller Prices'!$H:$H,MATCH($B5,'Controller Prices'!$B:$B,0))-$G5) | I5: =IF(OR($G5="",INDEX('Controller Prices'!$I:$I,MATCH($B5,'Controller Prices'!$B:$B,0))=""),"",INDEX('Controller Prices'!$I:$I,MATCH($B5,'Controller Prices'!$B:$B,0))-$G5) -> 90
A6: HotBox Kilns (120V) | B6: HB86 Vitrigraph | C6: Spark | D6: 1700 | E6: =IF(OR($C6="KilnStar",$D6="",INDEX('Controller Prices'!$D:$D,MATCH($B6,'Controller Prices'!$B:$B,0))=""),"",INDEX('Controller Prices'!$D:$D,MATCH($B6,'Controller Prices'!$B:$B,0))-$D6) -> -75 | F6: =IF(OR($D6="",INDEX('Controller Prices'!$E:$E,MATCH($B6,'Controller Prices'!$B:$B,0))=""),"",INDEX('Controller Prices'!$E:$E,MATCH($B6,'Controller Prices'!$B:$B,0))-$D6) -> 75 | G6: 1020 | H6: =IF(OR($C6="KilnStar",$G6="",INDEX('Controller Prices'!$H:$H,MATCH($B6,'Controller Prices'!$B:$B,0))=""),"",INDEX('Controller Prices'!$H:$H,MATCH($B6,'Controller Prices'!$B:$B,0))-$G6) -> -45 | I6: =IF(OR($G6="",INDEX('Controller Prices'!$I:$I,MATCH($B6,'Controller Prices'!$B:$B,0))=""),"",INDEX('Controller Prices'!$I:$I,MATCH($B6,'Controller Prices'!$B:$B,0))-$G6) -> 45
A7: 120 Volt Kilns | B7: HB89E | C7: KilnStar | D7: 1600 | E7: =IF(OR($C7="KilnStar",$D7="",INDEX('Controller Prices'!$D:$D,MATCH($B7,'Controller Prices'!$B:$B,0))=""),"",INDEX('Controller Prices'!$D:$D,MATCH($B7,'Controller Prices'!$B:$B,0))-$D7) | F7: =IF(OR($D7="",INDEX('Controller Prices'!$E:$E,MATCH($B7,'Controller Prices'!$B:$B,0))=""),"",INDEX('Controller Prices'!$E:$E,MATCH($B7,'Controller Prices'!$B:$B,0))-$D7) -> 125 | G7: 960 | H7: =IF(OR($C7="KilnStar",$G7="",INDEX('Controller Prices'!$H:$H,MATCH($B7,'Controller Prices'!$B:$B,0))=""),"",INDEX('Controller Prices'!$H:$H,MATCH($B7,'Controller Prices'!$B:$B,0))-$G7) | I7: =IF(OR($G7="",INDEX('Controller Prices'!$I:$I,MATCH($B7,'Controller Prices'!$B:$B,0))=""),"",INDEX('Controller Prices'!$I:$I,MATCH($B7,'Controller Prices'!$B:$B,0))-$G7) -> 75
A8: 120 Volt Kilns | B8: Doll/Test | C8: KilnStar | D8: 1710 | E8: =IF(OR($C8="KilnStar",$D8="",INDEX('Controller Prices'!$D:$D,MATCH($B8,'Controller Prices'!$B:$B,0))=""),"",INDEX('Controller Prices'!$D:$D,MATCH($B8,'Controller Prices'!$B:$B,0))-$D8) | F8: =IF(OR($D8="",INDEX('Controller Prices'!$E:$E,MATCH($B8,'Controller Prices'!$B:$B,0))=""),"",INDEX('Controller Prices'!$E:$E,MATCH($B8,'Controller Prices'!$B:$B,0))-$D8) -> 120 | G8: 1026 | H8: =IF(OR($C8="KilnStar",$G8="",INDEX('Controller Prices'!$H:$H,MATCH($B8,'Controller Prices'!$B:$B,0))=""),"",INDEX('Controller Prices'!$H:$H,MATCH($B8,'Controller Prices'!$B:$B,0))-$G8) | I8: =IF(OR($G8="",INDEX('Controller Prices'!$I:$I,MATCH($B8,'Controller Prices'!$B:$B,0))=""),"",INDEX('Controller Prices'!$I:$I,MATCH($B8,'Controller Prices'!$B:$B,0))-$G8) -> 72
A9: 120 Volt Kilns | B9: Traveler | C9: KilnStar | D9: 2200 | E9: =IF(OR($C9="KilnStar",$D9="",INDEX('Controller Prices'!$D:$D,MATCH($B9,'Controller Prices'!$B:$B,0))=""),"",INDEX('Controller Prices'!$D:$D,MATCH($B9,'Controller Prices'!$B:$B,0))-$D9) | F9: =IF(OR($D9="",INDEX('Controller Prices'!$E:$E,MATCH($B9,'Controller Prices'!$B:$B,0))=""),"",INDEX('Controller Prices'!$E:$E,MATCH($B9,'Controller Prices'!$B:$B,0))-$D9) -> 150 | G9: 1320 | H9: =IF(OR($C9="KilnStar",$G9="",INDEX('Controller Prices'!$H:$H,MATCH($B9,'Controller Prices'!$B:$B,0))=""),"",INDEX('Controller Prices'!$H:$H,MATCH($B9,'Controller Prices'!$B:$B,0))-$G9) | I9: =IF(OR($G9="",INDEX('Controller Prices'!$I:$I,MATCH($B9,'Controller Prices'!$B:$B,0))=""),"",INDEX('Controller Prices'!$I:$I,MATCH($B9,'Controller Prices'!$B:$B,0))-$G9) -> 90
A10: 120 Volt Kilns | B10: 126 Lite | C10: KilnStar | D10: 1450 | E10: =IF(OR($C10="KilnStar",$D10="",INDEX('Controller Prices'!$D:$D,MATCH($B10,'Controller Prices'!$B:$B,0))=""),"",INDEX('Controller Prices'!$D:$D,MATCH($B10,'Controller Prices'!$B:$B,0))-$D10) | F10: =IF(OR($D10="",INDEX('Controller Prices'!$E:$E,MATCH($B10,'Controller Prices'!$B:$B,0))=""),"",INDEX('Controller Prices'!$E:$E,MATCH($B10,'Controller Prices'!$B:$B,0))-$D10) -> 150 | G10: 870 | H10: =IF(OR($C10="KilnStar",$G10="",INDEX('Controller Prices'!$H:$H,MATCH($B10,'Controller Prices'!$B:$B,0))=""),"",INDEX('Controller Prices'!$H:$H,MATCH($B10,'Controller Prices'!$B:$B,0))-$G10) | I10: =IF(OR($G10="",INDEX('Controller Prices'!$I:$I,MATCH($B10,'Controller Prices'!$B:$B,0))=""),"",INDEX('Controller Prices'!$I:$I,MATCH($B10,'Controller Prices'!$B:$B,0))-$G10) -> 90
A11: 120 Volt Kilns | B11: 129E | C11: KilnStar | D11: 1785 | E11: =IF(OR($C11="KilnStar",$D11="",INDEX('Controller Prices'!$D:$D,MATCH($B11,'Controller Prices'!$B:$B,0))=""),"",INDEX('Controller Prices'!$D:$D,MATCH($B11,'Controller Prices'!$B:$B,0))-$D11) | F11: =IF(OR($D11="",INDEX('Controller Prices'!$E:$E,MATCH($B11,'Controller Prices'!$B:$B,0))=""),"",INDEX('Controller Prices'!$E:$E,MATCH($B11,'Controller Prices'!$B:$B,0))-$D11) -> 150 | G11: 1071 | H11: =IF(OR($C11="KilnStar",$G11="",INDEX('Controller Prices'!$H:$H,MATCH($B11,'Controller Prices'!$B:$B,0))=""),"",INDEX('Controller Prices'!$H:$H,MATCH($B11,'Controller Prices'!$B:$B,0))-$G11) | I11: =IF(OR($G11="",INDEX('Controller Prices'!$I:$I,MATCH($B11,'Controller Prices'!$B:$B,0))=""),"",INDEX('Controller Prices'!$I:$I,MATCH($B11,'Controller Prices'!$B:$B,0))-$G11) -> 90
A12: 120 Volt Kilns | B12: 1214-120E | C12: KilnStar | D12: 1965 | E12: =IF(OR($C12="KilnStar",$D12="",INDEX('Controller Prices'!$D:$D,MATCH($B12,'Controller Prices'!$B:$B,0))=""),"",INDEX('Controller Prices'!$D:$D,MATCH($B12,'Controller Prices'!$B:$B,0))-$D12) | F12: =IF(OR($D12="",INDEX('Controller Prices'!$E:$E,MATCH($B12,'Controller Prices'!$B:$B,0))=""),"",INDEX('Controller Prices'!$E:$E,MATCH($B12,'Controller Prices'!$B:$B,0))-$D12) -> 120 | G12: 1179 | H12: =IF(OR($C12="KilnStar",$G12="",INDEX('Controller Prices'!$H:$H,MATCH($B12,'Controller Prices'!$B:$B,0))=""),"",INDEX('Controller Prices'!$H:$H,MATCH($B12,'Controller Prices'!$B:$B,0))-$G12) | I12: =IF(OR($G12="",INDEX('Controller Prices'!$I:$I,MATCH($B12,'Controller Prices'!$B:$B,0))=""),"",INDEX('Controller Prices'!$I:$I,MATCH($B12,'Controller Prices'!$B:$B,0))-$G12) -> 72
A13: 120 Volt Kilns | B13: 1214-120HE | C13: KilnStar | D13: 2100 | E13: =IF(OR($C13="KilnStar",$D13="",INDEX('Controller Prices'!$D:$D,MATCH($B13,'Controller Prices'!$B:$B,0))=""),"",INDEX('Controller Prices'!$D:$D,MATCH($B13,'Controller Prices'!$B:$B,0))-$D13) | F13: =IF(OR($D13="",INDEX('Controller Prices'!$E:$E,MATCH($B13,'Controller Prices'!$B:$B,0))=""),"",INDEX('Controller Prices'!$E:$E,MATCH($B13,'Controller Prices'!$B:$B,0))-$D13) -> 120 | G13: 1260 | H13: =IF(OR($C13="KilnStar",$G13="",INDEX('Controller Prices'!$H:$H,MATCH($B13,'Controller Prices'!$B:$B,0))=""),"",INDEX('Controller Prices'!$H:$H,MATCH($B13,'Controller Prices'!$B:$B,0))-$G13) | I13: =IF(OR($G13="",INDEX('Controller Prices'!$I:$I,MATCH($B13,'Controller Prices'!$B:$B,0))=""),"",INDEX('Controller Prices'!$I:$I,MATCH($B13,'Controller Prices'!$B:$B,0))-$G13) -> 72
... A54: 23" Wide Stackable Kilns (240/208V) | B54: 2318E | C54: KilnStar | D54: 3925 | E54: =IF(OR($C54="KilnStar",$D54="",INDEX('Controller Prices'!$D:$D,MATCH($B54,'Controller Prices'!$B:$B,0))=""),"",INDEX('Controller Prices'!$D:$D,MATCH($B54,'Controller Prices'!$B:$B,0))-$D54) | F54: =IF(OR($D54="",INDEX('Controller Prices'!$E:$E,MATCH($B54,'Controller Prices'!$B:$B,0))=""),"",INDEX('Controller Prices'!$E:$E,MATCH($B54,'Controller Prices'!$B:$B,0))-$D54) -> 150 | G54: 2355 | H54: =IF(OR($C54="KilnStar",$G54="",INDEX('Controller Prices'!$H:$H,MATCH($B54,'Controller Prices'!$B:$B,0))=""),"",INDEX('Controller Prices'!$H:$H,MATCH($B54,'Controller Prices'!$B:$B,0))-$G54) | I54: =IF(OR($G54="",INDEX('Controller Prices'!$I:$I,MATCH($B54,'Controller Prices'!$B:$B,0))=""),"",INDEX('Controller Prices'!$I:$I,MATCH($B54,'Controller Prices'!$B:$B,0))-$G54) -> 90
A55: 23" Wide Stackable Kilns (240/208V) | B55: 2318HE | C55: KilnStar | D55: 4000 | E55: =IF(OR($C55="KilnStar",$D55="",INDEX('Controller Prices'!$D:$D,MATCH($B55,'Controller Prices'!$B:$B,0))=""),"",INDEX('Controller Prices'!$D:$D,MATCH($B55,'Controller Prices'!$B:$B,0))-$D55) | F55: =IF(OR($D55="",INDEX('Controller Prices'!$E:$E,MATCH($B55,'Controller Prices'!$B:$B,0))=""),"",INDEX('Controller Prices'!$E:$E,MATCH($B55,'Controller Prices'!$B:$B,0))-$D55) -> 150 | H55: =IF(OR($C55="KilnStar",$G55="",INDEX('Controller Prices'!$H:$H,MATCH($B55,'Controller Prices'!$B:$B,0))=""),"",INDEX('Controller Prices'!$H:$H,MATCH($B55,'Controller Prices'!$B:$B,0))-$G55) | I55: =IF(OR($G55="",INDEX('Controller Prices'!$I:$I,MATCH($B55,'Controller Prices'!$B:$B,0))=""),"",INDEX('Controller Prices'!$I:$I,MATCH($B55,'Controller Prices'!$B:$B,0))-$G55)
A56: 23" Wide Stackable Kilns (240/208V) | B56: 2323HE | C56: KilnStar | D56: 4610 | E56: =IF(OR($C56="KilnStar",$D56="",INDEX('Controller Prices'!$D:$D,MATCH($B56,'Controller Prices'!$B:$B,0))=""),"",INDEX('Controller Prices'!$D:$D,MATCH($B56,'Controller Prices'!$B:$B,0))-$D56) | F56: =IF(OR($D56="",INDEX('Controller Prices'!$E:$E,MATCH($B56,'Controller Prices'!$B:$B,0))=""),"",INDEX('Controller Prices'!$E:$E,MATCH($B56,'Controller Prices'!$B:$B,0))-$D56) -> 150 | G56: 2766 | H56: =IF(OR($C56="KilnStar",$G56="",INDEX('Controller Prices'!$H:$H,MATCH($B56,'Controller Prices'!$B:$B,0))=""),"",INDEX('Controller Prices'!$H:$H,MATCH($B56,'Controller Prices'!$B:$B,0))-$G56) | I56: =IF(OR($G56="",INDEX('Controller Prices'!$I:$I,MATCH($B56,'Controller Prices'!$B:$B,0))=""),"",INDEX('Controller Prices'!$I:$I,MATCH($B56,'Controller Prices'!$B:$B,0))-$G56) -> 90
A57: 23" Wide Stackable Kilns (240/208V) | B57: 2327E | C57: KilnStar | D57: 4835 | E57: =IF(OR($C57="KilnStar",$D57="",INDEX('Controller Prices'!$D:$D,MATCH($B57,'Controller Prices'!$B:$B,0))=""),"",INDEX('Controller Prices'!$D:$D,MATCH($B57,'Controller Prices'!$B:$B,0))-$D57) | F57: =IF(OR($D57="",INDEX('Controller Prices'!$E:$E,MATCH($B57,'Controller Prices'!$B:$B,0))=""),"",INDEX('Controller Prices'!$E:$E,MATCH($B57,'Controller Prices'!$B:$B,0))-$D57) -> 160 | G57: 2901 | H57: =IF(OR($C57="KilnStar",$G57="",INDEX('Controller Prices'!$H:$H,MATCH($B57,'Controller Prices'!$B:$B,0))=""),"",INDEX('Controller Prices'!$H:$H,MATCH($B57,'Controller Prices'!$B:$B,0))-$G57) | I57: =IF(OR($G57="",INDEX('Controller Prices'!$I:$I,MATCH($B57,'Controller Prices'!$B:$B,0))=""),"",INDEX('Controller Prices'!$I:$I,MATCH($B57,'Controller Prices'!$B:$B,0))-$G57) -> 96
A58: 23" Wide Stackable Kilns (240/208V) | B58: 2327HE | C58: KilnStar | D58: 5100 | E58: =IF(OR($C58="KilnStar",$D58="",INDEX('Controller Prices'!$D:$D,MATCH($B58,'Controller Prices'!$B:$B,0))=""),"",INDEX('Controller Prices'!$D:$D,MATCH($B58,'Controller Prices'!$B:$B,0))-$D58) | F58: =IF(OR($D58="",INDEX('Controller Prices'!$E:$E,MATCH($B58,'Controller Prices'!$B:$B,0))=""),"",INDEX('Controller Prices'!$E:$E,MATCH($B58,'Controller Prices'!$B:$B,0))-$D58) -> 150 | G58: 3060 | H58: =IF(OR($C58="KilnStar",$G58="",INDEX('Controller Prices'!$H:$H,MATCH($B58,'Controller Prices'!$B:$B,0))=""),"",INDEX('Controller Prices'!$H:$H,MATCH($B58,'Controller Prices'!$B:$B,0))-$G58) | I58: =IF(OR($G58="",INDEX('Controller Prices'!$I:$I,MATCH($B58,'Controller Prices'!$B:$B,0))=""),"",INDEX('Controller Prices'!$I:$I,MATCH($B58,'Controller Prices'!$B:$B,0))-$G58) -> 90
A59: 23" Wide Stackable Kilns (240/208V) | B59: 2331HE | C59: KilnStar | D59: 5300 | E59: =IF(OR($C59="KilnStar",$D59="",INDEX('Controller Prices'!$D:$D,MATCH($B59,'Controller Prices'!$B:$B,0))=""),"",INDEX('Controller Prices'!$D:$D,MATCH($B59,'Controller Prices'!$B:$B,0))-$D59) | F59: =IF(OR($D59="",INDEX('Controller Prices'!$E:$E,MATCH($B59,'Controller Prices'!$B:$B,0))=""),"",INDEX('Controller Prices'!$E:$E,MATCH($B59,'Controller Prices'!$B:$B,0))-$D59) -> 150 | G59: 3180 | H59: =IF(OR($C59="KilnStar",$G59="",INDEX('Controller Prices'!$H:$H,MATCH($B59,'Controller Prices'!$B:$B,0))=""),"",INDEX('Controller Prices'!$H:$H,MATCH($B59,'Controller Prices'!$B:$B,0))-$G59) | I59: =IF(OR($G59="",INDEX('Controller Prices'!$I:$I,MATCH($B59,'Controller Prices'!$B:$B,0))=""),"",INDEX('Controller Prices'!$I:$I,MATCH($B59,'Controller Prices'!$B:$B,0))-$G59) -> 90
A60: 20" & 25" Wide Square Kilns (240/208V) | B60: GF2E | C60: KilnStar | D60: 3700 | E60: =IF(OR($C60="KilnStar",$D60="",INDEX('Controller Prices'!$D:$D,MATCH($B60,'Controller Prices'!$B:$B,0))=""),"",INDEX('Controller Prices'!$D:$D,MATCH($B60,'Controller Prices'!$B:$B,0))-$D60) | F60: =IF(OR($D60="",INDEX('Controller Prices'!$E:$E,MATCH($B60,'Controller Prices'!$B:$B,0))=""),"",INDEX('Controller Prices'!$E:$E,MATCH($B60,'Controller Prices'!$B:$B,0))-$D60) -> 150 | G60: 2220 | H60: =IF(OR($C60="KilnStar",$G60="",INDEX('Controller Prices'!$H:$H,MATCH($B60,'Controller Prices'!$B:$B,0))=""),"",INDEX('Controller Prices'!$H:$H,MATCH($B60,'Controller Prices'!$B:$B,0))-$G60) | I60: =IF(OR($G60="",INDEX('Controller Prices'!$I:$I,MATCH($B60,'Controller Prices'!$B:$B,0))=""),"",INDEX('Controller Prices'!$I:$I,MATCH($B60,'Controller Prices'!$B:$B,0))-$G60) -> 90
A61: 20" & 25" Wide Square Kilns (240/208V) | B61: GF2ETLC | C61: KilnStar | D61: 3950 | E61: =IF(OR($C61="KilnStar",$D61="",INDEX('Controller Prices'!$D:$D,MATCH($B61,'Controller Prices'!$B:$B,0))=""),"",INDEX('Controller Prices'!$D:$D,MATCH($B61,'Controller Prices'!$B:$B,0))-$D61) | F61: =IF(OR($D61="",INDEX('Controller Prices'!$E:$E,MATCH($B61,'Controller Prices'!$B:$B,0))=""),"",INDEX('Controller Prices'!$E:$E,MATCH($B61,'Controller Prices'!$B:$B,0))-$D61) -> 150 | G61: 2370 | H61: =IF(OR($C61="KilnStar",$G61="",INDEX('Controller Prices'!$H:$H,MATCH($B61,'Controller Prices'!$B:$B,0))=""),"",INDEX('Controller Prices'!$H:$H,MATCH($B61,'Controller Prices'!$B:$B,0))-$G61) | I61: =IF(OR($G61="",INDEX('Controller Prices'!$I:$I,MATCH($B61,'Controller Prices'!$B:$B,0))=""),"",INDEX('Controller Prices'!$I:$I,MATCH($B61,'Controller Prices'!$B:$B,0))-$G61) -> 90
A62: 20" & 25" Wide Square Kilns (240/208V) | B62: GF214E | C62: KilnStar | D62: 4050 | E62: =IF(OR($C62="KilnStar",$D62="",INDEX('Controller Prices'!$D:$D,MATCH($B62,'Controller Prices'!$B:$B,0))=""),"",INDEX('Controller Prices'!$D:$D,MATCH($B62,'Controller Prices'!$B:$B,0))-$D62) | F62: =IF(OR($D62="",INDEX('Controller Prices'!$E:$E,MATCH($B62,'Controller Prices'!$B:$B,0))=""),"",INDEX('Controller Prices'!$E:$E,MATCH($B62,'Controller Prices'!$B:$B,0))-$D62) -> 150 | G62: 2430 | H62: =IF(OR($C62="KilnStar",$G62="",INDEX('Controller Prices'!$H:$H,MATCH($B62,'Controller Prices'!$B:$B,0))=""),"",INDEX('Controller Prices'!$H:$H,MATCH($B62,'Controller Prices'!$B:$B,0))-$G62) | I62: =IF(OR($G62="",INDEX('Controller Prices'!$I:$I,MATCH($B62,'Controller Prices'!$B:$B,0))=""),"",INDEX('Controller Prices'!$I:$I,MATCH($B62,'Controller Prices'!$B:$B,0))-$G62) -> 90
A63: 20" & 25" Wide Square Kilns (240/208V) | B63: GF214ETLC | C63: KilnStar | D63: 4400 | E63: =IF(OR($C63="KilnStar",$D63="",INDEX('Controller Prices'!$D:$D,MATCH($B63,'Controller Prices'!$B:$B,0))=""),"",INDEX('Controller Prices'!$D:$D,MATCH($B63,'Controller Prices'!$B:$B,0))-$D63) | F63: =IF(OR($D63="",INDEX('Controller Prices'!$E:$E,MATCH($B63,'Controller Prices'!$B:$B,0))=""),"",INDEX('Controller Prices'!$E:$E,MATCH($B63,'Controller Prices'!$B:$B,0))-$D63) -> 150 | G63: 2640 | H63: =IF(OR($C63="KilnStar",$G63="",INDEX('Controller Prices'!$H:$H,MATCH($B63,'Controller Prices'!$B:$B,0))=""),"",INDEX('Controller Prices'!$H:$H,MATCH($B63,'Controller Prices'!$B:$B,0))-$G63) | I63: =IF(OR($G63="",INDEX('Controller Prices'!$I:$I,MATCH($B63,'Controller Prices'!$B:$B,0))=""),"",INDEX('Controller Prices'!$I:$I,MATCH($B63,'Controller Prices'!$B:$B,0))-$G63) -> 90
A64: 20" & 25" Wide Square Kilns (240/208V) | B64: GF3E | C64: KilnStar | D64: 3950 | E64: =IF(OR($C64="KilnStar",$D64="",INDEX('Controller Prices'!$D:$D,MATCH($B64,'Controller Prices'!$B:$B,0))=""),"",INDEX('Controller Prices'!$D:$D,MATCH($B64,'Controller Prices'!$B:$B,0))-$D64) | F64: =IF(OR($D64="",INDEX('Controller Prices'!$E:$E,MATCH($B64,'Controller Prices'!$B:$B,0))=""),"",INDEX('Controller Prices'!$E:$E,MATCH($B64,'Controller Prices'!$B:$B,0))-$D64) -> 150 | G64: 2370 | H64: =IF(OR($C64="KilnStar",$G64="",INDEX('Controller Prices'!$H:$H,MATCH($B64,'Controller Prices'!$B:$B,0))=""),"",INDEX('Controller Prices'!$H:$H,MATCH($B64,'Controller Prices'!$B:$B,0))-$G64) | I64: =IF(OR($G64="",INDEX('Controller Prices'!$I:$I,MATCH($B64,'Controller Prices'!$B:$B,0))=""),"",INDEX('Controller Prices'!$I:$I,MATCH($B64,'Controller Prices'!$B:$B,0))-$G64) -> 90
A65: 20" & 25" Wide Square Kilns (240/208V) | B65: GF3ETLC | C65: KilnStar | D65: 4250 | E65: =IF(OR($C65="KilnStar",$D65="",INDEX('Controller Prices'!$D:$D,MATCH($B65,'Controller Prices'!$B:$B,0))=""),"",INDEX('Controller Prices'!$D:$D,MATCH($B65,'Controller Prices'!$B:$B,0))-$D65) | F65: =IF(OR($D65="",INDEX('Controller Prices'!$E:$E,MATCH($B65,'Controller Prices'!$B:$B,0))=""),"",INDEX('Controller Prices'!$E:$E,MATCH($B65,'Controller Prices'!$B:$B,0))-$D65) -> 150 | G65: 2550 | H65: =IF(OR($C65="KilnStar",$G65="",INDEX('Controller Prices'!$H:$H,MATCH($B65,'Controller Prices'!$B:$B,0))=""),"",INDEX('Controller Prices'!$H:$H,MATCH($B65,'Controller Prices'!$B:$B,0))-$G65) | I65: =IF(OR($G65="",INDEX('Controller Prices'!$I:$I,MATCH($B65,'Controller Prices'!$B:$B,0))=""),"",INDEX('Controller Prices'!$I:$I,MATCH($B65,'Controller Prices'!$B:$B,0))-$G65) -> 90
A66: 20" & 25" Wide Square Kilns (240/208V) | B66: GF314E | C66: KilnStar | D66: 4625 | E66: =IF(OR($C66="KilnStar",$D66="",INDEX('Controller Prices'!$D:$D,MATCH($B66,'Controller Prices'!$B:$B,0))=""),"",INDEX('Controller Prices'!$D:$D,MATCH($B66,'Controller Prices'!$B:$B,0))-$D66) | F66: =IF(OR($D66="",INDEX('Controller Prices'!$E:$E,MATCH($B66,'Controller Prices'!$B:$B,0))=""),"",INDEX('Controller Prices'!$E:$E,MATCH($B66,'Controller Prices'!$B:$B,0))-$D66) -> 150 | G66: 2775 | H66: =IF(OR($C66="KilnStar",$G66="",INDEX('Controller Prices'!$H:$H,MATCH($B66,'Controller Prices'!$B:$B,0))=""),"",INDEX('Controller Prices'!$H:$H,MATCH($B66,'Controller Prices'!$B:$B,0))-$G66) | I66: =IF(OR($G66="",INDEX('Controller Prices'!$I:$I,MATCH($B66,'Controller Prices'!$B:$B,0))=""),"",INDEX('Controller Prices'!$I:$I,MATCH($B66,'Controller Prices'!$B:$B,0))-$G66) -> 90
A67: 20" & 25" Wide Square Kilns (240/208V) | B67: GF314ETLC | C67: KilnStar | D67: 4950 | E67: =IF(OR($C67="KilnStar",$D67="",INDEX('Controller Prices'!$D:$D,MATCH($B67,'Controller Prices'!$B:$B,0))=""),"",INDEX('Controller Prices'!$D:$D,MATCH($B67,'Controller Prices'!$B:$B,0))-$D67) | F67: =IF(OR($D67="",INDEX('Controller Prices'!$E:$E,MATCH($B67,'Controller Prices'!$B:$B,0))=""),"",INDEX('Controller Prices'!$E:$E,MATCH($B67,'Controller Prices'!$B:$B,0))-$D67) -> 150 | G67: 2970 | H67: =IF(OR($C67="KilnStar",$G67="",INDEX('Controller Prices'!$H:$H,MATCH($B67,'Controller Prices'!$B:$B,0))=""),"",INDEX('Controller Prices'!$H:$H,MATCH($B67,'Controller Prices'!$B:$B,0))-$G67) | I67: =IF(OR($G67="",INDEX('Controller Prices'!$I:$I,MATCH($B67,'Controller Prices'!$B:$B,0))=""),"",INDEX('Controller Prices'!$I:$I,MATCH($B67,'Controller Prices'!$B:$B,0))-$G67) -> 90
... A141: Large Capacity Kilns | B141: FL12E Car | C141: KilnStar | D141: 13800 | E141: =IF(OR($C141="KilnStar",$D141="",INDEX('Controller Prices'!$D:$D,MATCH($B141,'Controller Prices'!$B:$B,0))=""),"",INDEX('Controller Prices'!$D:$D,MATCH($B141,'Controller Prices'!$B:$B,0))-$D141) | F141: =IF(OR($D141="",INDEX('Controller Prices'!$E:$E,MATCH($B141,'Controller Prices'!$B:$B,0))=""),"",INDEX('Controller Prices'!$E:$E,MATCH($B141,'Controller Prices'!$B:$B,0))-$D141) -> 150 | G141: 9660 | H141: =IF(OR($C141="KilnStar",$G141="",INDEX('Controller Prices'!$H:$H,MATCH($B141,'Controller Prices'!$B:$B,0))=""),"",INDEX('Controller Prices'!$H:$H,MATCH($B141,'Controller Prices'!$B:$B,0))-$G141) | I141: =IF(OR($G141="",INDEX('Controller Prices'!$I:$I,MATCH($B141,'Controller Prices'!$B:$B,0))=""),"",INDEX('Controller Prices'!$I:$I,MATCH($B141,'Controller Prices'!$B:$B,0))-$G141) -> 105
A142: Large Capacity Kilns | B142: GF12E | C142: KilnStar | D142: 12000 | E142: =IF(OR($C142="KilnStar",$D142="",INDEX('Controller Prices'!$D:$D,MATCH($B142,'Controller Prices'!$B:$B,0))=""),"",INDEX('Controller Prices'!$D:$D,MATCH($B142,'Controller Prices'!$B:$B,0))-$D142) | F142: =IF(OR($D142="",INDEX('Controller Prices'!$E:$E,MATCH($B142,'Controller Prices'!$B:$B,0))=""),"",INDEX('Controller Prices'!$E:$E,MATCH($B142,'Controller Prices'!$B:$B,0))-$D142) -> 150 | H142: =IF(OR($C142="KilnStar",$G142="",INDEX('Controller Prices'!$H:$H,MATCH($B142,'Controller Prices'!$B:$B,0))=""),"",INDEX('Controller Prices'!$H:$H,MATCH($B142,'Controller Prices'!$B:$B,0))-$G142) | I142: =IF(OR($G142="",INDEX('Controller Prices'!$I:$I,MATCH($B142,'Controller Prices'!$B:$B,0))=""),"",INDEX('Controller Prices'!$I:$I,MATCH($B142,'Controller Prices'!$B:$B,0))-$G142)
A143: Large Capacity Kilns | B143: GE12E CS | C143: KilnStar | D143: 13500 | E143: =IF(OR($C143="KilnStar",$D143="",INDEX('Controller Prices'!$D:$D,MATCH($B143,'Controller Prices'!$B:$B,0))=""),"",INDEX('Controller Prices'!$D:$D,MATCH($B143,'Controller Prices'!$B:$B,0))-$D143) | F143: =IF(OR($D143="",INDEX('Controller Prices'!$E:$E,MATCH($B143,'Controller Prices'!$B:$B,0))=""),"",INDEX('Controller Prices'!$E:$E,MATCH($B143,'Controller Prices'!$B:$B,0))-$D143) -> 150 | G143: 9450 | H143: =IF(OR($C143="KilnStar",$G143="",INDEX('Controller Prices'!$H:$H,MATCH($B143,'Controller Prices'!$B:$B,0))=""),"",INDEX('Controller Prices'!$H:$H,MATCH($B143,'Controller Prices'!$B:$B,0))-$G143) | I143: =IF(OR($G143="",INDEX('Controller Prices'!$I:$I,MATCH($B143,'Controller Prices'!$B:$B,0))=""),"",INDEX('Controller Prices'!$I:$I,MATCH($B143,'Controller Prices'!$B:$B,0))-$G143) -> 105
A144: Large Capacity Kilns | B144: GF12ETLC | C144: KilnStar | D144: 15650 | E144: =IF(OR($C144="KilnStar",$D144="",INDEX('Controller Prices'!$D:$D,MATCH($B144,'Controller Prices'!$B:$B,0))=""),"",INDEX('Controller Prices'!$D:$D,MATCH($B144,'Controller Prices'!$B:$B,0))-$D144) | F144: =IF(OR($D144="",INDEX('Controller Prices'!$E:$E,MATCH($B144,'Controller Prices'!$B:$B,0))=""),"",INDEX('Controller Prices'!$E:$E,MATCH($B144,'Controller Prices'!$B:$B,0))-$D144) -> 150 | G144: 10955 | H144: =IF(OR($C144="KilnStar",$G144="",INDEX('Controller Prices'!$H:$H,MATCH($B144,'Controller Prices'!$B:$B,0))=""),"",INDEX('Controller Prices'!$H:$H,MATCH($B144,'Controller Prices'!$B:$B,0))-$G144) | I144: =IF(OR($G144="",INDEX('Controller Prices'!$I:$I,MATCH($B144,'Controller Prices'!$B:$B,0))=""),"",INDEX('Controller Prices'!$I:$I,MATCH($B144,'Controller Prices'!$B:$B,0))-$G144) -> 105
A145: Large Capacity Kilns | B145: GF15E | C145: KilnStar | D145: 12850 | E145: =IF(OR($C145="KilnStar",$D145="",INDEX('Controller Prices'!$D:$D,MATCH($B145,'Controller Prices'!$B:$B,0))=""),"",INDEX('Controller Prices'!$D:$D,MATCH($B145,'Controller Prices'!$B:$B,0))-$D145) | F145: =IF(OR($D145="",INDEX('Controller Prices'!$E:$E,MATCH($B145,'Controller Prices'!$B:$B,0))=""),"",INDEX('Controller Prices'!$E:$E,MATCH($B145,'Controller Prices'!$B:$B,0))-$D145) -> 150 | G145: 8995 | H145: =IF(OR($C145="KilnStar",$G145="",INDEX('Controller Prices'!$H:$H,MATCH($B145,'Controller Prices'!$B:$B,0))=""),"",INDEX('Controller Prices'!$H:$H,MATCH($B145,'Controller Prices'!$B:$B,0))-$G145) | I145: =IF(OR($G145="",INDEX('Controller Prices'!$I:$I,MATCH($B145,'Controller Prices'!$B:$B,0))=""),"",INDEX('Controller Prices'!$I:$I,MATCH($B145,'Controller Prices'!$B:$B,0))-$G145) -> 105
A146: Large Capacity Kilns | B146: GF15E CS | C146: KilnStar | D146: 14500 | E146: =IF(OR($C146="KilnStar",$D146="",INDEX('Controller Prices'!$D:$D,MATCH($B146,'Controller Prices'!$B:$B,0))=""),"",INDEX('Controller Prices'!$D:$D,MATCH($B146,'Controller Prices'!$B:$B,0))-$D146) | F146: =IF(OR($D146="",INDEX('Controller Prices'!$E:$E,MATCH($B146,'Controller Prices'!$B:$B,0))=""),"",INDEX('Controller Prices'!$E:$E,MATCH($B146,'Controller Prices'!$B:$B,0))-$D146) -> 110 | G146: 10150 | H146: =IF(OR($C146="KilnStar",$G146="",INDEX('Controller Prices'!$H:$H,MATCH($B146,'Controller Prices'!$B:$B,0))=""),"",INDEX('Controller Prices'!$H:$H,MATCH($B146,'Controller Prices'!$B:$B,0))-$G146) | I146: =IF(OR($G146="",INDEX('Controller Prices'!$I:$I,MATCH($B146,'Controller Prices'!$B:$B,0))=""),"",INDEX('Controller Prices'!$I:$I,MATCH($B146,'Controller Prices'!$B:$B,0))-$G146) -> 77
A147: Large Capacity Kilns | B147: GF15ETLC | C147: KilnStar | D147: 14650 | E147: =IF(OR($C147="KilnStar",$D147="",INDEX('Controller Prices'!$D:$D,MATCH($B147,'Controller Prices'!$B:$B,0))=""),"",INDEX('Controller Prices'!$D:$D,MATCH($B147,'Controller Prices'!$B:$B,0))-$D147) | F147: =IF(OR($D147="",INDEX('Controller Prices'!$E:$E,MATCH($B147,'Controller Prices'!$B:$B,0))=""),"",INDEX('Controller Prices'!$E:$E,MATCH($B147,'Controller Prices'!$B:$B,0))-$D147) -> 110 | G147: 10255 | H147: =IF(OR($C147="KilnStar",$G147="",INDEX('Controller Prices'!$H:$H,MATCH($B147,'Controller Prices'!$B:$B,0))=""),"",INDEX('Controller Prices'!$H:$H,MATCH($B147,'Controller Prices'!$B:$B,0))-$G147) | I147: =IF(OR($G147="",INDEX('Controller Prices'!$I:$I,MATCH($B147,'Controller Prices'!$B:$B,0))=""),"",INDEX('Controller Prices'!$I:$I,MATCH($B147,'Controller Prices'!$B:$B,0))-$G147) -> 77
A148: Large Capacity Kilns | B148: FL17E | C148: KilnStar | D148: 13675 | E148: =IF(OR($C148="KilnStar",$D148="",INDEX('Controller Prices'!$D:$D,MATCH($B148,'Controller Prices'!$B:$B,0))=""),"",INDEX('Controller Prices'!$D:$D,MATCH($B148,'Controller Prices'!$B:$B,0))-$D148) | F148: =IF(OR($D148="",INDEX('Controller Prices'!$E:$E,MATCH($B148,'Controller Prices'!$B:$B,0))=""),"",INDEX('Controller Prices'!$E:$E,MATCH($B148,'Controller Prices'!$B:$B,0))-$D148) -> 150 | G148: 9572.5 | H148: =IF(OR($C148="KilnStar",$G148="",INDEX('Controller Prices'!$H:$H,MATCH($B148,'Controller Prices'!$B:$B,0))=""),"",INDEX('Controller Prices'!$H:$H,MATCH($B148,'Controller Prices'!$B:$B,0))-$G148) | I148: =IF(OR($G148="",INDEX('Controller Prices'!$I:$I,MATCH($B148,'Controller Prices'!$B:$B,0))=""),"",INDEX('Controller Prices'!$I:$I,MATCH($B148,'Controller Prices'!$B:$B,0))-$G148) -> 105
A149: Large Capacity Kilns | B149: FL17E Car | C149: KilnStar | D149: 17050 | E149: =IF(OR($C149="KilnStar",$D149="",INDEX('Controller Prices'!$D:$D,MATCH($B149,'Controller Prices'!$B:$B,0))=""),"",INDEX('Controller Prices'!$D:$D,MATCH($B149,'Controller Prices'!$B:$B,0))-$D149) | F149: =IF(OR($D149="",INDEX('Controller Prices'!$E:$E,MATCH($B149,'Controller Prices'!$B:$B,0))=""),"",INDEX('Controller Prices'!$E:$E,MATCH($B149,'Controller Prices'!$B:$B,0))-$D149) -> 250 | G149: 11935 | H149: =IF(OR($C149="KilnStar",$G149="",INDEX('Controller Prices'!$H:$H,MATCH($B149,'Controller Prices'!$B:$B,0))=""),"",INDEX('Controller Prices'!$H:$H,MATCH($B149,'Controller Prices'!$B:$B,0))-$G149) | I149: =IF(OR($G149="",INDEX('Controller Prices'!$I:$I,MATCH($B149,'Controller Prices'!$B:$B,0))=""),"",INDEX('Controller Prices'!$I:$I,MATCH($B149,'Controller Prices'!$B:$B,0))-$G149) -> 175
A150: Large Capacity Kilns | B150: GF17E | C150: KilnStar | D150: 13550 | E150: =IF(OR($C150="KilnStar",$D150="",INDEX('Controller Prices'!$D:$D,MATCH($B150,'Controller Prices'!$B:$B,0))=""),"",INDEX('Controller Prices'!$D:$D,MATCH($B150,'Controller Prices'!$B:$B,0))-$D150) | F150: =IF(OR($D150="",INDEX('Controller Prices'!$E:$E,MATCH($B150,'Controller Prices'!$B:$B,0))=""),"",INDEX('Controller Prices'!$E:$E,MATCH($B150,'Controller Prices'!$B:$B,0))-$D150) -> 150 | G150: 9485 | H150: =IF(OR($C150="KilnStar",$G150="",INDEX('Controller Prices'!$H:$H,MATCH($B150,'Controller Prices'!$B:$B,0))=""),"",INDEX('Controller Prices'!$H:$H,MATCH($B150,'Controller Prices'!$B:$B,0))-$G150) | I150: =IF(OR($G150="",INDEX('Controller Prices'!$I:$I,MATCH($B150,'Controller Prices'!$B:$B,0))=""),"",INDEX('Controller Prices'!$I:$I,MATCH($B150,'Controller Prices'!$B:$B,0))-$G150) -> 2450
A151: Large Capacity Kilns | B151: GF17E CS | C151: KilnStar | D151: 14800 | E151: =IF(OR($C151="KilnStar",$D151="",INDEX('Controller Prices'!$D:$D,MATCH($B151,'Controller Prices'!$B:$B,0))=""),"",INDEX('Controller Prices'!$D:$D,MATCH($B151,'Controller Prices'!$B:$B,0))-$D151) | F151: =IF(OR($D151="",INDEX('Controller Prices'!$E:$E,MATCH($B151,'Controller Prices'!$B:$B,0))=""),"",INDEX('Controller Prices'!$E:$E,MATCH($B151,'Controller Prices'!$B:$B,0))-$D151) -> 150 | G151: 9485 | H151: =IF(OR($C151="KilnStar",$G151="",INDEX('Controller Prices'!$H:$H,MATCH($B151,'Controller Prices'!$B:$B,0))=""),"",INDEX('Controller Prices'!$H:$H,MATCH($B151,'Controller Prices'!$B:$B,0))-$G151) | I151: =IF(OR($G151="",INDEX('Controller Prices'!$I:$I,MATCH($B151,'Controller Prices'!$B:$B,0))=""),"",INDEX('Controller Prices'!$I:$I,MATCH($B151,'Controller Prices'!$B:$B,0))-$G151) -> 16065
A152: Large Capacity Kilns | B152: GF17ETLC | C152: KilnStar | D152: 16900 | E152: =IF(OR($C152="KilnStar",$D152="",INDEX('Controller Prices'!$D:$D,MATCH($B152,'Controller Prices'!$B:$B,0))=""),"",INDEX('Controller Prices'!$D:$D,MATCH($B152,'Controller Prices'!$B:$B,0))-$D152) | F152: =IF(OR($D152="",INDEX('Controller Prices'!$E:$E,MATCH($B152,'Controller Prices'!$B:$B,0))=""),"",INDEX('Controller Prices'!$E:$E,MATCH($B152,'Controller Prices'!$B:$B,0))-$D152) -> 150 | G152: 11830 | H152: =IF(OR($C152="KilnStar",$G152="",INDEX('Controller Prices'!$H:$H,MATCH($B152,'Controller Prices'!$B:$B,0))=""),"",INDEX('Controller Prices'!$H:$H,MATCH($B152,'Controller Prices'!$B:$B,0))-$G152) | I152: =IF(OR($G152="",INDEX('Controller Prices'!$I:$I,MATCH($B152,'Controller Prices'!$B:$B,0))=""),"",INDEX('Controller Prices'!$I:$I,MATCH($B152,'Controller Prices'!$B:$B,0))-$G152) -> 105
A153: Large Capacity Kilns | B153: FL20E | C153: KilnStar | D153: 15625 | E153: =IF(OR($C153="KilnStar",$D153="",INDEX('Controller Prices'!$D:$D,MATCH($B153,'Controller Prices'!$B:$B,0))=""),"",INDEX('Controller Prices'!$D:$D,MATCH($B153,'Controller Prices'!$B:$B,0))-$D153) | F153: =IF(OR($D153="",INDEX('Controller Prices'!$E:$E,MATCH($B153,'Controller Prices'!$B:$B,0))=""),"",INDEX('Controller Prices'!$E:$E,MATCH($B153,'Controller Prices'!$B:$B,0))-$D153) -> 125 | G153: 10937.5 | H153: =IF(OR($C153="KilnStar",$G153="",INDEX('Controller Prices'!$H:$H,MATCH($B153,'Controller Prices'!$B:$B,0))=""),"",INDEX('Controller Prices'!$H:$H,MATCH($B153,'Controller Prices'!$B:$B,0))-$G153) | I153: =IF(OR($G153="",INDEX('Controller Prices'!$I:$I,MATCH($B153,'Controller Prices'!$B:$B,0))=""),"",INDEX('Controller Prices'!$I:$I,MATCH($B153,'Controller Prices'!$B:$B,0))-$G153) -> 87.5
...

Sheet Controller Prices
A1: Category | B1: Model # | C1: Spark | D1: KilnStar | E1: Genesis | F1: Burners w/ Ignition | G1: Spark D$ | H1: KilnStar D$ | I1: Genesis D$ | J1: Burners D$
A2: HotBox Kilns (120V) | B2: HB64E | C2: 1235 | G2: 741
A3: HotBox Kilns (120V) | B3: HotboxE | C3: 1365 | G3: 819
A4: HotBox Kilns (120V) | B4: HB84E | C4: 1525 | G4: 915
A5: HotBox Kilns (120V) | B5: HB86E | D5: 1450 | E5: 1600 | H5: 870 | I5: 960
A6: HotBox Kilns (120V) | B6: HB86 Vitrigraph | C6: 1700 | D6: 1625 | E6: 1775 | G6: 1020 | H6: 975 | I6: 1065
A7: 120 Volt Kilns | B7: HB89E | D7: 1600 | E7: 1725 | H7: 960 | I7: 1035
A8: 120 Volt Kilns | B8: Doll/Test | D8: 1710 | E8: 1830 | H8: 1026 | I8: 1098
A9: 120 Volt Kilns | B9: Traveler | D9: 2200 | E9: 2350 | H9: 1320 | I9: 1410
A10: 120 Volt Kilns | B10: 126 Lite | D10: 1450 | E10: 1600 | H10: 870 | I10: 960
A11: 120 Volt Kilns | B11: 129E | D11: 1785 | E11: 1935 | H11: 1071 | I11: 1161
A12: 120 Volt Kilns | B12: 1214-120E | D12: 1965 | E12: 2085 | H12: 1179 | I12: 1251
A13: 120 Volt Kilns | B13: 1214-120HE | D13: 2100 | E13: 2220 | H13: 1260 | I13: 1332
A14: 120 Volt Kilns | B14: Champ | D14: 1585 | E14: 1735 | H14: 951 | I14: 1041
A15: 120 Volt Kilns | B15: Champ XL | D15: 1725 | E15: 1875 | H15: 1035 | I15: 1125
A16: 120 Volt Kilns | B16: Square 146GFE | D16: 1850 | E16: 2000 | H16: 1110 | I16: 1200
A17: 120 Volt Kilns | B17: Square 146GFECS | D17: 2050 | E17: 2200 | H17: 1230 | I17: 1320
A18: 120 Volt Kilns | B18: Square 146GFETLC | D18: 2300 | E18: 2450 | H18: 1380 | I18: 1470
... A54: 23" Wide Stackable Kilns (240/208V) | B54: 2318E | D54: 3925 | E54: 4075 | H54: 2355 | I54: 2445
A55: 23" Wide Stackable Kilns (240/208V) | B55: 2318HE | D55: 4000 | E55: 4150
A56: 23" Wide Stackable Kilns (240/208V) | B56: 2323HE | D56: 4610 | E56: 4760 | H56: 2766 | I56: 2856
A57: 23" Wide Stackable Kilns (240/208V) | B57: 2327E | D57: 4835 | E57: 4995 | H57: 2901 | I57: 2997
A58: 23" Wide Stackable Kilns (240/208V) | B58: 2327HE | D58: 5100 | E58: 5250 | H58: 3060 | I58: 3150
A59: 23" Wide Stackable Kilns (240/208V) | B59: 2331HE | D59: 5300 | E59: 5450 | H59: 3180 | I59: 3270
A60: 20" & 25" Wide Square Kilns (240/208V) | B60: GF2E | D60: 3700 | E60: 3850 | H60: 2220 | I60: 2310
A61: 20" & 25" Wide Square Kilns (240/208V) | B61: GF2ETLC | D61: 3950 | E61: 4100 | H61: 2370 | I61: 2460
A62: 20" & 25" Wide Square Kilns (240/208V) | B62: GF214E | D62: 4050 | E62: 4200 | H62: 2430 | I62: 2520
A63: 20" & 25" Wide Square Kilns (240/208V) | B63: GF214ETLC | D63: 4400 | E63: 4550 | H63: 2640 | I63: 2730
A64: 20" & 25" Wide Square Kilns (240/208V) | B64: GF3E | D64: 3950 | E64: 4100 | H64: 2370 | I64: 2460
A65: 20" & 25" Wide Square Kilns (240/208V) | B65: GF3ETLC | D65: 4250 | E65: 4400 | H65: 2550 | I65: 2640
A66: 20" & 25" Wide Square Kilns (240/208V) | B66: GF314E | D66: 4625 | E66: 4775 | H66: 2775 | I66: 2865
A67: 20" & 25" Wide Square Kilns (240/208V) | B67: GF314ETLC | D67: 4950 | E67: 5100 | H67: 2970 | I67: 3060
... A141: Large Capacity Kilns | B141: FL12E Car | D141: 13800 | E141: 13950 | H141: 9660 | I141: 9765
A142: Large Capacity Kilns | B142: GF12E | D142: 12000 | E142: 12150
A143: Large Capacity Kilns | B143: GE12E CS | D143: 13500 | E143: 13650 | H143: 9450 | I143: 9555
A144: Large Capacity Kilns | B144: GF12ETLC | D144: 15650 | E144: 15800 | H144: 10955 | I144: 11060
A145: Large Capacity Kilns | B145: GF15E | D145: 12850 | E145: 13000 | H145: 8995 | I145: 9100
A146: Large Capacity Kilns | B146: GF15E CS | D146: 14500 | E146: 14610 | H146: 10150 | I146: 10227
A147: Large Capacity Kilns | B147: GF15ETLC | D147: 14650 | E147: 14760 | H147: 10255 | I147: 10332
A148: Large Capacity Kilns | B148: FL17E | D148: 13675 | E148: 13825 | H148: 9572.5 | I148: 9677.5
...

Sheet Furniture Kits
A1: Series | B1: Fits Model(s) | C1: Kit Contents | D1: Ship Wt. (lbs.) | E1: List Price | F1: Distributor $
A2: 120 Volt Kilns | B2: HB64E, HOTBOX E | C2: 2-5.5" x 5.5" square shelves, 4 ea-1/2, 1, 2 inch small posts, l lb. bag of kiln wash | D2: 12 | E2: 100 | F2: 60
A3: 120 Volt Kilns | B3: HB84E, HB86E, HB89E | C3: 2-6.5" x 6.5" square shelves, 4 ea-1/2, 1, 2 inch small posts, 1 sq. ft. of ceramic paper, 1 lb. bag of kiln wash | D3: 12 | E3: 108 | F3: 64.8
A4: 120 Volt Kilns | B4: DOLL E/TEST E | C4: 2-10" x 6" oval shelves, 4 ea-1/2, 1, 2 inch small posts, l lb. bag of kiln wash | D4: 12 | E4: 115 | F4: 69
A5: 120 Volt Kilns | B5: 129E, 1214-120E, 1214-120HE | C5: 2-10" x 10" round shelves, 3 ea-1-6 inch small posts, l lb. bag of kiln wash | D5: 20 | E5: 160 | F5: 96
A6: 120 Volt Kilns | B6: TRAVELER | C6: 3-10" x 10" square shelves, 4 ea-1-6 inch small posts, l lb. bag of kiln wash, 3 sq. ft. of ceramic paper | D6: 30 | E6: 260 | F6: 156
A7: 120 Volt Kilns | B7: 126 Lite | C7: 2-10" x 10" square shelves, 4 ea-1/2, 1, 2 inch small posts, 1 sq. ft. of ceramic paper | D7: 10 | E7: 128 | F7: 76.8
A8: 120 Volt Kilns | B8: 14" Square | C8: 2-13" x 13" square shelves, 4 ea-1/2, 1, 2 inch small posts, 2 sq. ft. of ceramic paper | D8: 25 | E8: 185 | F8: 111
A9: 120 Volt Kilns | B9: 16" Square | C9: 2-15" x 15" square shelves, 4 ea-1/2, 1, 2- inch small posts, 2 sq. ft. of ceramic paper | D9: 45 | E9: 205 | F9: 123
A10: 120 Volt Kilns | B10: 18" Square | C10: 2-16" x 16" square shelves, 4 ea-1/2, 1, 2- inch small posts, 2 sq. ft. of ceramic paper | D10: 55 | E10: 215 | F10: 129
A11: Studio Front Loading Kilns | B11: 129FLE, 139FLE | C11: 2 ea. - 9" x 7" rectangle shelves, 4 ea. - 1, 3, 5 inch small square posts, l lb. of kiln wash | D11: 20 | E11: 145 | F11: 87
A12: Studio Front Loading Kilns | B12: 1214FLE | C12: 2 ea. - 9" x 12" rectangle shelves, 4 ea. - 1, 3, 5 inch small square posts, l lb. of kiln wash | D12: 22 | E12: 180 | F12: 108
A13: Studio Front Loading Kilns | B13: 149FLE | C13: 2 ea. -12" x 7" rectangle shelves, 4 ea. - 1, 3, 5 inch small square posts, l lb. of kiln wash | D13: 22 | E13: 180 | F13: 108
... A80: DownDraft (DD) Gas Kilns | B80: DD40 | C80: 16 ea. - 20" x 20" x 1" shelves, 16 ea. - 3, 6, 9, 12 inch large posts, 5 lb. bag of kiln wash | D80: 505 | E80: 2585 | F80: 1809.5

Sheet Accessories
A1: Item | B1: Description | C1: List Price | D1: D$ Studio | E1: D$ Large Cap.
A2: 3 Phase Wiring-Studio Line/Large Capacity | B2: How a building is wired to run electricity through it, either 1 or 3 phase | C2: $110/$450 | D2: 66 | E2: 315
A3: 2 Zone Control | B3: Two thermocouples installed in kiln to regulate temperatures at the top, center and bottom sections | C3: 150 | D3: 90 | E3: 105
A4: 3 Zone Control | B4: Three thermocouples installed in kiln to regulate temperatures at the top, center and bottom sections | C4: 295 | D4: 177 | E4: 206.5
A5: 480 volt | B5: Optional voltage | C5: 550 | D5: 330 | E5: 385
A6: Assorted Stilt Kit | B6: 30 Assorted Stilts for Stilting Ware When Glazing | C6: 85 | D6: 51
A7: Automatic Lid Shut-off | B7: Safety Shut-off when kiln lid is opened | C7: 115 | D7: 69 | E7: 80.5
A8: Blower Burner 200k (per burner) | B8: Alternative firing method for DD models/Burner on Kiln | C8: 1425 | D8: 997.5
A9: Blower Burner 200k (per burner) | B9: Alternative firing method for DD models/Burner Stand Alone | C9: 1700 | D9: 1190
A10: HB Blank Collar | B10: Inside dimensions: 8" x 8" w x 4.5" h, 23 lbs. | C10: 265 | D10: 159
A11: HB Bead Collar | B11: Inside dimensions: 8" x 8" w x 4.5" h, 23 lbs. | C11: 295 | D11: 177
A12: HB Fiber Floor | B12: HotBox Fiber Floor for Vitrigraph, 8" x 8" x 1", 15 lbs. | C12: 80 | D12: 48
A13: 18" Blank Ring | B13: Inside dimensions: 17.5" w x 4.5" h, 30 lbs. | C13: 300 | D13: 180
A14: 18H" Blank Ring | B14: Inside dimensions: 17.5" w x 4.5" h, 36 lbs. | C14: 350 | D14: 210
A15: 23" Blank Ring | B15: Inside dimensions: 23 3/8" w x 4.5" h, 40 lbs. | C15: 350 | D15: 210
A16: 23H" Blank Ring | B16: Inside dimensions: 23 3/8" w x 4.5" h, 45 lbs. | C16: 405 | D16: 243
A17: 28/28H" Blank Ring | B17: Inside dimensions: 28.25" w x 4.5" h, 90 lbs. | C17: 475 | D17: 285
A18: 20/20H" Blank Ring | B18: Inside dimensions: 30" w x 20" d x 4.5" h, 65 lbs. | C18: 480 | D18: 288
A19: 25/25H" Blank Ring | B19: Inside dimensions: 37" w x 25" d x 4.5" h, 70 lbs. | C19: 560 | D19: 336
... A21: Bead Door | B21: Small flip-up door installed on the body or the door of the GLASS kiln for annealing. | C21: 115 | D21: 69
A22: Castors-Studio Kilns | B22: Wheels for Studio Kilns with 8" tall stand or frame | C22: 325 | E22: 195
A23: Castors- Large Capacity Kilns | B23: Wheels for Large Capacity Kilns | C23: 450 | E23: 315
A24: CE Wiring | B24: European Wiring Specifications | C24: 275 | D24: 165 | E24: 222
A25: Ceramic Paper | B25: 1/8" thick - sold by the square foot | C25: 10 | D25: 6
A26: Dual Media (DM) Lid Element | B26: Lid element added to a non-dual media kiln at the time of ordering | C26: 650 | D26: 390
A27: Electro Sitter | B27: Equipped with KilnStar Controller | C27: 1250 | D27: 750
A28: Electro Sitter | B28: Equipped with Genesis 2.0 Controller | C28: 1450 | D28: 870
A29: Flash Arm (Glass Kilns) | B29: Studio Sized GLASS Kilns only, Notched arm to hold lid in place while flash venting or combing glass. | C29: 115 | D29: 69
A30: Gloves | B30: Heavy- duty, insulated | C30: 70 | D30: 42
A31: Guillotine Lift | B31: Studio Front Loading Kilns | C31: 395 | D31: 237
A32: Guillotine Lift | B32: Large Capacity Front Loading Kilns | C32: Call for Pricing
A33: High Limit Controller | B33: Electronic controller for GAS kilns which sets target temperature and when reached, controller shuts down the kiln. Requires 120 volt receptacle | C33: 1600 | D33: 960
A34: Kiln Wash | B34: 1 lb. bag | C34: 6.5 | D34: 3.9
A35: Kiln Wash | B35: 5 lb. bag | C35: 25 | E35: 17.5
A36: Lid Assist | B36: New kiln purchases for smaller production, studio kilns that do not come with a Lid Lift | C36: 550 | D36: 330
A37: Lid Assist - Retro Fit | B37: Available for kilns which were purchased without a lid lift | C37: 750 | D37: 450
A38: Lid Elements in Quartz Rods | B38: Studio GLASS Kilns | C38: 850 | D38: 510
A39: Lid Elements in Quartz Rods | B39: Large Capacity GLASS Kilns | C39: Call for Pricing
A40: Lid Wedge | B40: Vents kiln (not for use on oval kilns) | C40: 20 | D40: 12
A41: Low Pressure Regulator 18" | B41: For 18" Raku and Torchbearer GAS kilns | C41: 175 | D41: 105
...

Sheet Kiln Shelves
A1: Shelf | B1: Dimensions | C1: Shape | D1: Wt. (lbs.) | E1: List Price | F1: D$ Studio | G1: D$ Large Cap.
A2: HB64, HotBox Shelf | B2: 5.5" x 5.5" | C2: Square | D2: 4 | E2: 31 | F2: 18.6
A3: HB84,HB86, HB89 Shelf | B3: 6.5 x 6.5" | C3: Square | D3: 4 | E3: 31 | F3: 18.6
A4: Doll/Test Shelf | B4: 10" x 6" | C4: Oval | D4: 4 | E4: 35 | F4: 21
A5: 12-12H" Shelf | B5: 10" x 10" | C5: Round | D5: 5 | E5: 40 | F5: 24
A6: 126 Liite, Traveler Shelf | B6: 10" x 10" | C6: Square | D6: 6 | E6: 41 | F6: 24.6
A7: 129FL, 139FL Shelf | B7: 9" x 7" | C7: Rectangle | D7: 6 | E7: 43 | F7: 25.8
A8: 1214FL Shelf | B8: 12" x 9" | C8: Rectangle | D8: 8 | E8: 60 | F8: 36
A9: 149FL Shelf | B9: 12" x 7" | C9: Rectangle | D9: 8 | E9: 60 | F9: 36
A10: 1414FL Shelf | B10: 12" x 11" | C10: Rectangle | D10: 10 | E10: 75 | F10: 45
A11: 1818FL Shelf | B11: 16" x 16" | C11: Square | D11: 29 | E11: 80 | F11: 48
A12: 1823FL Shelf | B12: 16" x 20" | C12: Rectangle | D12: 35 | E12: 95 | F12: 57
A13: 14H" Half Shelf | B13: 13" x 6.5" | C13: Rectangle | D13: 8 | E13: 34 | F13: 20.4
... A33: 25H" Half Shelf | B33: 21" x 10.5" x 1" | C33: Half Round | D33: 28 | E33: 75 | F33: 45
A34: 25H" Center Shelf, DD9, TL4828, TL4832 FL8, FL10, FL12, FL42, FL53 Shelf | B34: 22" x 11" x 1" | C34: Rectangle | D34: 28 | E34: 110 | F34: 66 | G34: 77
A35: 25H" Full Shelf | B35: 21" x 32" x 1" | C35: Oval | D35: 50 | E35: 375 | F35: 225
A36: 30H" Half Shelf | B36: 26" x 13" x 1" | C36: Half Round | D36: 34 | E36: 115 | F36: 69
A37: 30H" Center Shelf. DD12, FL17, FL20, TL20 Shelf | B37: 26" x 13" x 1" | C37: Rectangle | D37: 34 | E37: 115 | F37: 69 | G37: 80.5
A38: 30H" Full Shelf | B38: 26" x 39" x 1" | C38: Oval | D38: 64 | E38: 425 | F38: 255
A39: DD20 | B39: 15" x 15" x 1" | C39: Square | D39: 27 | E39: 95 | G39: 66.5
A40: DD24, FL4.5, FL24 Shelf | B40: 16" x 16" x 1" | C40: Square | D40: 19 | E40: 100 | G40: 70
A41: FL5.5, FL36 Shelf | B41: 18" x 18" x 1" | C41: Square | D41: 23 | E41: 105 | G41: 73.5
A42: FL27, FL31 Shelf | B42: 17" x 17" x 1" | C42: Square | D42: 21 | E42: 105 | G42: 73.5
A43: FL64 Shelf | B43: 23 x 23" x 1" | C43: Square | D43: 33 | E43: 140 | G43: 98
A44: DD30, GF2s | B44: 18" x 18" x 1" | C44: Square | D44: 21 | E44: 115 | F44: 69 | G44: 88.55
A45: DD40 | B45: 20" x 20" x 1" | C45: Square | D45: 40 | E45: 125 | G45: 87.5
A46: GF3s | B46: 23" x 23" x 1" | C46: Square | D46: 23 | E46: 140 | F46: 84
A47: GF5s | B47: 27" x 27" | C47: Square | D47: 37 | E47: 275 | F47: 165
A48: TL24 Shelf | B48: 20" x 11" x 1" | C48: Rectangle | D48: 16 | E48: 110 | G48: 77
A49: TL5428, TL5432 Shelf | B49: 26" x 11" x 1" | C49: Rectangle | D49: 30 | E49: 115 | G49: 80.5
A50: DD14, DD17 | B50: 28" x 14" x 1" | C50: Rectangle | D50: 35 | E50: 115 | G50: 80.5

Sheet Kiln Posts
A1: Post Type | B1: Size | C1: List Price | D1: D$ Studio | E1: D$ Large Cap.
A2: Small (1" x 1" square) | B2: 1/2 Inch | C2: 2.5 | D2: 1.5
A3: Small (1" x 1" square) | B3: 1 inch | C3: 3 | D3: 1.8
A4: Small (1" x 1" square) | B4: 2 inch | C4: 3.5 | D4: 2.1
A5: Small (1" x 1" square) | B5: 3 inch | C5: 4 | D5: 2.4
A6: Small (1" x 1" square) | B6: 4 inch | C6: 4.5 | D6: 2.7
A7: Small (1" x 1" square) | B7: 5 inch | C7: 5 | D7: 3
A8: Small (1" x 1" square) | B8: 6 inch | C8: 6.5 | D8: 3.9
A9: Small (1" x 1" square) | B9: 8 inch | C9: 8.5 | D9: 5.1
A10: Large (1 1/2" x 1 1/2" square) | B10: 1/2 Inch | C10: 3 | D10: 1.8 | E10: 2.1
A11: Large (1 1/2" x 1 1/2" square) | B11: 1 inch | C11: 3.25 | D11: 1.95 | E11: 2.27
A12: Large (1 1/2" x 1 1/2" square) | B12: 2 inch | C12: 3.75 | D12: 2.25 | E12: 2.62
A13: Large (1 1/2" x 1 1/2" square) | B13: 3 inch | C13: 4.5 | D13: 2.7 | E13: 3.15
A14: Large (1 1/2" x 1 1/2" square) | B14: 4 inch | C14: 6 | D14: 3.6 | E14: 4.2
A15: Large (1 1/2" x 1 1/2" square) | B15: 5 inch | C15: 6.95 | D15: 4.17 | E15: 4.87
A16: Large (1 1/2" x 1 1/2" square) | B16: 6 inch | C16: 8 | D16: 4.8 | E16: 5.6
A17: Large (1 1/2" x 1 1/2" square) | B17: 7 inch | C17: 8.75 | D17: 5.25 | E17: 6.12
A18: Large (1 1/2" x 1 1/2" square) | B18: 8 inch | C18: 9.75 | D18: 5.85 | E18: 6.82
A19: Large (1 1/2" x 1 1/2" square) | B19: 9 inch | C19: 10.75 | D19: 6.45 | E19: 7.52
A20: Large (1 1/2" x 1 1/2" square) | B20: 10 inch | C20: 11.75 | D20: 7.05 | E20: 8.22
A21: Large (1 1/2" x 1 1/2" square) | B21: 12 inch | C21: 13.75 | D21: 8.25 | E21: 9.62

Sheet Solid State Relays
A1: Amperage Limit | B1: Voltage | C1: Set Price, 1 Phase Wiring | D1: Add'l Relay, 2 or 3 Zone Under 50 Amps | E1: Add'l Relays, 3 Phase Wiring | F1: D$ 1 Phase | G1: D$ 2/3 Zone | H1: D$ 3 Phase
A2: Up to 20 Amps | B2: 120 | C2: 150 | D2: 425 | E2: 425 | F2: 90 | G2: 255 | H2: 255
A3: Up to 25 Amps | B3: 240/208 | C3: 300 | D3: 575 | E3: 575 | F3: 180 | G3: 345 | H3: 345
A4: 26-50 Amps | B4: 240/208 | C4: 425 | D4: 700 | E4: 700 | F4: 255 | G4: 420 | H4: 420
A5: 51-75 Amps | B5: 240/208 | C5: 545 | E5: 820 | F5: 327 | H5: 492
A6: 76-100 Amps | B6: 240/208 | C6: 650 | E6: 925 | F6: 390 | H6: 555
A7: 101-125 Amps | B7: 240/208 | C7: 775 | E7: 1050 | F7: 465 | H7: 630
A8: 126-150 Amps | B8: 240/208 | C8: 900 | E8: 1180 | F8: 540 | H8: 708
A9: 151-175 Amps | B9: 240/208 | C9: 1000 | E9: 1300 | F9: 600 | H9: 780
A10: 175-200 Amps | B10: 240/208 | C10: 1100 | E10: 1400 | F10: 660 | H10: 840

Sheet Notes
A1: Olympic Kilns — 2026 Pricing (effective OCT 2026)
A2: Source: 2026_New_Pricing_OCT26.xlsx, sheet "Sheet1". Prices are copied from that file, not calculated,
A3: except for the corrections listed below.
A4: Olympic Kilns, PO Box 1347, 4225 Thurmon Tanner Pkwy., Flowery Branch, GA 30542 — Sales (800) 241-4400 — olympickilns.com
A6: How the Kilns sheet works
A7: One row per model. Base Price is the model with its base controller — Spark where it is offered, otherwise
A8: KilnStar; gas kilns are priced as "Burners w/ Ignition System" and have no controller options.
A9: Upgrade to KilnStar / Upgrade to Genesis = what that controller ADDS to the base price, not the total.
A10: A blank upgrade means the controller is either the base or not offered on that model.
A11: Those upgrade columns are formulas driven by the Controller Prices sheet, which lists the full price of every
A12: model/controller combination exactly as printed in the source — edit a price there and the upgrades follow.
A13: Distributor $ / D$ columns are the source's "D$" distributor prices (Studio line 40% off list, Large Capacity
... A42: • Made in the USA.
